Workbook
Name AutomationOptions: Lists!$C$2:$C$4
Name CheckOptions: Lists!$D$2:$D$3
Name DecisionOptions: Lists!$H$2:$H$5
Name DefectStatusOptions: Lists!$F$2:$F$6
Name PriorityOptions: Lists!$B$2:$B$5
Name RetestOptions: Lists!$E$2:$E$6
Name ScopeOptions: Lists!$I$2:$I$3
Name SeverityOptions: Lists!$G$2:$G$5
Name StatusOptions: Lists!$A$2:$A$7
Name TestTypeOptions: Lists!$J$2:$J$10

Sheet V4 SQA Report
A1: Robotics Programming Lab - v4 SQA Verification Report
A3: Release | B3: v4 Local Classroom-Ready Candidate | C3: Branch | D3: staging main - local only | E3: Test Date | F3: 46239
A4: Commit | B4: Working tree; not pushed | C4: Frontend | D4: http://localhost:8080 | E4: Backend | F4: http://127.0.0.1:5000
A5: Scope | B5: Local-only classroom-readiness verification. No live repository push or production deployment was performed. Render restart, production PostgreSQL rollback, and another physical computer/network remain external live gates.
A7: Total Checks | B7: 60 | C7: Passed | D7: 47 | E7: Non-Pass / Open | F7: 13
A8: Pass Rate | B8: 0.78333333 | C8: Blocked | D8: 0 | E8: Not Run / Deferred | F8: 6
A9: Decision | B9: LOCAL GATE PASSED - LIVE EXTERNAL GATES OPEN
A12: Check ID | B12: Area / Feature | C12: Result | D12: Environment | E12: Evidence | F12: Limitation / Next Step
A13: V4-SQA-001 | B13: Source and tracked-secret audit | C13: Pass | D13: Local repository | E13: Clean tracked source; venv ignored; one synthetic migration URL scanner match. | F13: No real credential detected in tracked files.
A14: V4-SQA-002 | B14: 87 backend tests passed in the final local gate. | C14: Pass | D14: Local | E14: 87 pytest checks passed, including classroom error paths, restart persistence, manual accounts, and rollback rehearsal. | F14: Includes auth, assignment, grader, migration, rate-limit, remote-sandbox, and sandbox-service tests.
A15: V4-SQA-003 | B15: Python dependency integrity | C15: Pass | D15: Local | E15: pip check: no broken requirements. | F15: Fresh Python 3.11 venv created from backend requirements.
A16: V4-SQA-004 | B16: Python compilation | C16: Pass | D16: Local | E16: compileall completed without error. | F16: Backend modules compile.
A17: V4-SQA-005 | B17: Flutter static analysis | C17: Pass | D17: Local | E17: flutter analyze: no issues found. | F17: Current v4 source.
A18: V4-SQA-006 | B18: Flutter automated tests | C18: Pass | D18: Local | E18: 33 Flutter tests passed, including 390x844 layout and Ctrl+Enter keyboard execution. | F18: Includes login entry, session policy, responsive UI, progress, execution state, and secure-grader loading.
A19: V4-SQA-007 | B19: Flutter release web build | C19: Pass | D19: Local | E19: Production web build completed in .flutter_build/web. | F19: Built with the live Render API URL.
A20: V4-SQA-008 | B20: Hosted CI and deployment | C20: Pass | D20: GitHub/Vercel | E20: Latest v4 verification and Vercel deployment succeeded. | F20: Existing hosted baseline passed; new classroom-security working tree is not yet pushed or deployed.
A21: V4-SQA-009 | B21: Live health and exact-origin CORS | C21: Pass | D21: Render | E21: Health API 4.0.0; exact Vercel origin allowed. | F21: Live API checks passed.
A22: V4-SQA-010 | B22: Login-first shared URL | C22: Pass | D22: Live Chrome | E22: Public root displayed login despite prior saved session. | F22: Demo credentials were not shown on the page.
A23: V4-SQA-011 | B23: Invalid login handling | C23: Pass | D23: Live Chrome/API | E23: Invalid credential returned a clear error and remained on login. | F23: No endless spinner or crash.
... A72: V4-SQA-060 | B72: Manual Python answers for Assignments 1-4 | C72: Pass | D72: Local API/automated | E72: Four private-repository answer files independently scored 100%; classroom tests load these files as their regression source. | F72: The application and student APIs do not serve this folder or hidden tests.

Sheet Release Dashboard
A1: Robotics Programming Lab - SQA Release Dashboard
A2: Complete the Master Checklist for every release. Attach evidence, link defects, retest fixes, and obtain sign-off before publishing.
A4: Release / Version | B4: v4 Local Classroom-Ready Candidate | C4: Branch | D4: staging main - local only | E4: Commit | F4: Working tree - not pushed | G4: Test Date | H4: 46239
A5: SQA Owner | B5: Codex SQA | C5: Environment | D5: Local full stack + browser | E5: Backend URL | F5: http://127.0.0.1:5000 | G5: Frontend Target | H5: Chrome / Flutter Web / 390x844 test
A6: Scope Notes | B6: All executable local gates passed. Actual Render/Neon restart, production PostgreSQL rollback/restore, second-device/network test, and full accessibility audit remain open before live classroom release.
A8: Release Readiness
A9: Metric | B9: Value | C9: Metric | D9: Value | E9: Metric | F9: Value | G9: Metric | H9: Value
A10: Total Checks | B10: =COUNTA('Master Checklist'!B2:B204) | C10: Current Scope | D10: =COUNTIF('Master Checklist'!C2:C204,"Current") | E10: Passed | F10: =COUNTIF('Master Checklist'!M2:M204,"Pass") | G10: Failed | H10: =COUNTIF('Master Checklist'!M2:M204,"Fail")
A11: Blocked | B11: =COUNTIF('Master Checklist'!M2:M204,"Blocked") | C11: Not Run | D11: =COUNTIF('Master Checklist'!M2:M204,"Not Run") | E11: Deferred | F11: =COUNTIF('Master Checklist'!M2:M204,"Deferred") | G11: N/A | H11: =COUNTIF('Master Checklist'!M2:M204,"N/A")
A12: Completion | B12: =IF(D10=0,0,(F10+H10+B11+H11)/D10) | C12: Pass Rate | D12: =IF((F10+H10)=0,0,F10/(F10+H10)) | E12: Release Gate Fail/Blocked | F12: =COUNTIFS('Master Checklist'!I2:I204,"Release Gate",'Master Checklist'!M2:M204,"Fail")+COUNTIFS('Master Checklist'!I2:I204,"Release Gate",'Master Checklist'!M2:M204,"Blocked") | G12: Decision | H12: =IF(F12>0,"DO NOT RELEASE",IF(D11>0,"TESTING INCOMPLETE","READY FOR SIGN-OFF"))
A14: Category Coverage
A15: Category | B15: Total | C15: Pass | D15: Fail | E15: Blocked | F15: Not Run | G15: N/A | H15: Progress
A16: Environment & Startup | B16: =COUNTIF('Master Checklist'!D2:D204,A16) | C16: =COUNTIFS('Master Checklist'!D2:D204,A16,'Master Checklist'!M2:M204,"Pass") | D16: =COUNTIFS('Master Checklist'!D2:D204,A16,'Master Checklist'!M2:M204,"Fail") | E16: =COUNTIFS('Master Checklist'!D2:D204,A16,'Master Checklist'!M2:M204,"Blocked") | F16: =COUNTIFS('Master Checklist'!D2:D204,A16,'Master Checklist'!M2:M204,"Not Run") | G16: =COUNTIFS('Master Checklist'!D2:D204,A16,'Master Checklist'!M2:M204,"N/A") | H16: =IF(B16=0,0,(C16+D16+E16+G16)/B16)
A17: Health & Public API | B17: =COUNTIF('Master Checklist'!D2:D204,A17) | C17: =COUNTIFS('Master Checklist'!D2:D204,A17,'Master Checklist'!M2:M204,"Pass") | D17: =COUNTIFS('Master Checklist'!D2:D204,A17,'Master Checklist'!M2:M204,"Fail") | E17: =COUNTIFS('Master Checklist'!D2:D204,A17,'Master Checklist'!M2:M204,"Blocked") | F17: =COUNTIFS('Master Checklist'!D2:D204,A17,'Master Checklist'!M2:M204,"Not Run") | G17: =COUNTIFS('Master Checklist'!D2:D204,A17,'Master Checklist'!M2:M204,"N/A") | H17: =IF(B17=0,0,(C17+D17+E17+G17)/B17)
A18: Student Catalog & Navigation | B18: =COUNTIF('Master Checklist'!D2:D204,A18) | C18: =COUNTIFS('Master Checklist'!D2:D204,A18,'Master Checklist'!M2:M204,"Pass") | D18: =COUNTIFS('Master Checklist'!D2:D204,A18,'Master Checklist'!M2:M204,"Fail") | E18: =COUNTIFS('Master Checklist'!D2:D204,A18,'Master Checklist'!M2:M204,"Blocked") | F18: =COUNTIFS('Master Checklist'!D2:D204,A18,'Master Checklist'!M2:M204,"Not Run") | G18: =COUNTIFS('Master Checklist'!D2:D204,A18,'Master Checklist'!M2:M204,"N/A") | H18: =IF(B18=0,0,(C18+D18+E18+G18)/B18)
A19: Assignment Workspace & Editor | B19: =COUNTIF('Master Checklist'!D2:D204,A19) | C19: =COUNTIFS('Master Checklist'!D2:D204,A19,'Master Checklist'!M2:M204,"Pass") | D19: =COUNTIFS('Master Checklist'!D2:D204,A19,'Master Checklist'!M2:M204,"Fail") | E19: =COUNTIFS('Master Checklist'!D2:D204,A19,'Master Checklist'!M2:M204,"Blocked") | F19: =COUNTIFS('Master Checklist'!D2:D204,A19,'Master Checklist'!M2:M204,"Not Run") | G19: =COUNTIFS('Master Checklist'!D2:D204,A19,'Master Checklist'!M2:M204,"N/A") | H19: =IF(B19=0,0,(C19+D19+E19+G19)/B19)
A20: Grading & Execution | B20: =COUNTIF('Master Checklist'!D2:D204,A20) | C20: =COUNTIFS('Master Checklist'!D2:D204,A20,'Master Checklist'!M2:M204,"Pass") | D20: =COUNTIFS('Master Checklist'!D2:D204,A20,'Master Checklist'!M2:M204,"Fail") | E20: =COUNTIFS('Master Checklist'!D2:D204,A20,'Master Checklist'!M2:M204,"Blocked") | F20: =COUNTIFS('Master Checklist'!D2:D204,A20,'Master Checklist'!M2:M204,"Not Run") | G20: =COUNTIFS('Master Checklist'!D2:D204,A20,'Master Checklist'!M2:M204,"N/A") | H20: =IF(B20=0,0,(C20+D20+E20+G20)/B20)
A21: Sandbox, Security & Privacy | B21: =COUNTIF('Master Checklist'!D2:D204,A21) | C21: =COUNTIFS('Master Checklist'!D2:D204,A21,'Master Checklist'!M2:M204,"Pass") | D21: =COUNTIFS('Master Checklist'!D2:D204,A21,'Master Checklist'!M2:M204,"Fail") | E21: =COUNTIFS('Master Checklist'!D2:D204,A21,'Master Checklist'!M2:M204,"Blocked") | F21: =COUNTIFS('Master Checklist'!D2:D204,A21,'Master Checklist'!M2:M204,"Not Run") | G21: =COUNTIFS('Master Checklist'!D2:D204,A21,'Master Checklist'!M2:M204,"N/A") | H21: =IF(B21=0,0,(C21+D21+E21+G21)/B21)
A22: Feedback & Tutoring | B22: =COUNTIF('Master Checklist'!D2:D204,A22) | C22: =COUNTIFS('Master Checklist'!D2:D204,A22,'Master Checklist'!M2:M204,"Pass") | D22: =COUNTIFS('Master Checklist'!D2:D204,A22,'Master Checklist'!M2:M204,"Fail") | E22: =COUNTIFS('Master Checklist'!D2:D204,A22,'Master Checklist'!M2:M204,"Blocked") | F22: =COUNTIFS('Master Checklist'!D2:D204,A22,'Master Checklist'!M2:M204,"Not Run") | G22: =COUNTIFS('Master Checklist'!D2:D204,A22,'Master Checklist'!M2:M204,"N/A") | H22: =IF(B22=0,0,(C22+D22+E22+G22)/B22)
A23: Solutions & Learning Progress | B23: =COUNTIF('Master Checklist'!D2:D204,A23) | C23: =COUNTIFS('Master Checklist'!D2:D204,A23,'Master Checklist'!M2:M204,"Pass") | D23: =COUNTIFS('Master Checklist'!D2:D204,A23,'Master Checklist'!M2:M204,"Fail") | E23: =COUNTIFS('Master Checklist'!D2:D204,A23,'Master Checklist'!M2:M204,"Blocked") | F23: =COUNTIFS('Master Checklist'!D2:D204,A23,'Master Checklist'!M2:M204,"Not Run") | G23: =COUNTIFS('Master Checklist'!D2:D204,A23,'Master Checklist'!M2:M204,"N/A") | H23: =IF(B23=0,0,(C23+D23+E23+G23)/B23)
A24: Instructor Assignment Studio | B24: =COUNTIF('Master Checklist'!D2:D204,A24) | C24: =COUNTIFS('Master Checklist'!D2:D204,A24,'Master Checklist'!M2:M204,"Pass") | D24: =COUNTIFS('Master Checklist'!D2:D204,A24,'Master Checklist'!M2:M204,"Fail") | E24: =COUNTIFS('Master Checklist'!D2:D204,A24,'Master Checklist'!M2:M204,"Blocked") | F24: =COUNTIFS('Master Checklist'!D2:D204,A24,'Master Checklist'!M2:M204,"Not Run") | G24: =COUNTIFS('Master Checklist'!D2:D204,A24,'Master Checklist'!M2:M204,"N/A") | H24: =IF(B24=0,0,(C24+D24+E24+G24)/B24)
A25: Authentication & Account Management | B25: =COUNTIF('Master Checklist'!D2:D204,A25) | C25: =COUNTIFS('Master Checklist'!D2:D204,A25,'Master Checklist'!M2:M204,"Pass") | D25: =COUNTIFS('Master Checklist'!D2:D204,A25,'Master Checklist'!M2:M204,"Fail") | E25: =COUNTIFS('Master Checklist'!D2:D204,A25,'Master Checklist'!M2:M204,"Blocked") | F25: =COUNTIFS('Master Checklist'!D2:D204,A25,'Master Checklist'!M2:M204,"Not Run") | G25: =COUNTIFS('Master Checklist'!D2:D204,A25,'Master Checklist'!M2:M204,"N/A") | H25: =IF(B25=0,0,(C25+D25+E25+G25)/B25)
A26: Assignment Content & Pedagogy | B26: =COUNTIF('Master Checklist'!D2:D204,A26) | C26: =COUNTIFS('Master Checklist'!D2:D204,A26,'Master Checklist'!M2:M204,"Pass") | D26: =COUNTIFS('Master Checklist'!D2:D204,A26,'Master Checklist'!M2:M204,"Fail") | E26: =COUNTIFS('Master Checklist'!D2:D204,A26,'Master Checklist'!M2:M204,"Blocked") | F26: =COUNTIFS('Master Checklist'!D2:D204,A26,'Master Checklist'!M2:M204,"Not Run") | G26: =COUNTIFS('Master Checklist'!D2:D204,A26,'Master Checklist'!M2:M204,"N/A") | H26: =IF(B26=0,0,(C26+D26+E26+G26)/B26)
A27: Responsive, Accessibility & Usability | B27: =COUNTIF('Master Checklist'!D2:D204,A27) | C27: =COUNTIFS('Master Checklist'!D2:D204,A27,'Master Checklist'!M2:M204,"Pass") | D27: =COUNTIFS('Master Checklist'!D2:D204,A27,'Master Checklist'!M2:M204,"Fail") | E27: =COUNTIFS('Master Checklist'!D2:D204,A27,'Master Checklist'!M2:M204,"Blocked") | F27: =COUNTIFS('Master Checklist'!D2:D204,A27,'Master Checklist'!M2:M204,"Not Run") | G27: =COUNTIFS('Master Checklist'!D2:D204,A27,'Master Checklist'!M2:M204,"N/A") | H27: =IF(B27=0,0,(C27+D27+E27+G27)/B27)
A28: Data, Infrastructure & Deployment | B28: =COUNTIF('Master Checklist'!D2:D204,A28) | C28: =COUNTIFS('Master Checklist'!D2:D204,A28,'Master Checklist'!M2:M204,"Pass") | D28: =COUNTIFS('Master Checklist'!D2:D204,A28,'Master Checklist'!M2:M204,"Fail") | E28: =COUNTIFS('Master Checklist'!D2:D204,A28,'Master Checklist'!M2:M204,"Blocked") | F28: =COUNTIFS('Master Checklist'!D2:D204,A28,'Master Checklist'!M2:M204,"Not Run") | G28: =COUNTIFS('Master Checklist'!D2:D204,A28,'Master Checklist'!M2:M204,"N/A") | H28: =IF(B28=0,0,(C28+D28+E28+G28)/B28)
A29: Automated Quality & Release | B29: =COUNTIF('Master Checklist'!D2:D204,A29) | C29: =COUNTIFS('Master Checklist'!D2:D204,A29,'Master Checklist'!M2:M204,"Pass") | D29: =COUNTIFS('Master Checklist'!D2:D204,A29,'Master Checklist'!M2:M204,"Fail") | E29: =COUNTIFS('Master Checklist'!D2:D204,A29,'Master Checklist'!M2:M204,"Blocked") | F29: =COUNTIFS('Master Checklist'!D2:D204,A29,'Master Checklist'!M2:M204,"Not Run") | G29: =COUNTIFS('Master Checklist'!D2:D204,A29,'Master Checklist'!M2:M204,"N/A") | H29: =IF(B29=0,0,(C29+D29+E29+G29)/B29)
A32: Open product/architecture plan

Sheet Master Checklist
A1: Checked? | B1: Check ID | C1: Scope | D1: Category | E1: Feature / Requirement | F1: Preconditions | G1: Test Steps | H1: Expected Result | I1: Priority | J1: Test Type | K1: Platform | L1: Automated? | M1: Status | N1: Defect ID | O1: Actual Result / Evidence | P1: Tester | Q1: Test Date | R1: Retest Status | S1: Notes
A2: [x] | B2: ENV-001 | C2: Current | D2: Environment & Startup | E2: Repository clone contains required source and configuration files | F2: Application dependencies are installed and the target environment is available. | G2: Clone the repository; verify backend, frontend, assignments, course_materials, Dockerfiles, Compose, README, and plan artifacts are present. | H2: Required project structure is complete and no required imported source file is missing. | I2: Release Gate | J2: Inspection | K2: Repository | L2: Partial | M2: Pass | O2: Fresh v4 local setup/install plus Flutter analyzer, 33 tests, and release web build passed on 2026-08-04. | P2: Codex SQA | Q2: 46238 | R2: Not Required
A3: [x] | B3: ENV-002 | C3: Current | D3: Environment & Startup | E3: Secrets are not committed | F3: Application dependencies are installed and the target environment is available. | G3: Run Git secret and tracked-file checks; inspect .gitignore and tracked files for .env, API keys, admin tokens, databases, and credentials. | H3: No secret, backend/.env, database, or credential value is tracked. | I3: Release Gate | J3: Security | K3: Repository | L3: Partial | M3: Pass | O3: Fresh v4 local setup/install plus Flutter analyzer, 33 tests, and release web build passed on 2026-08-04. | P3: Codex SQA | Q3: 46238 | R3: Not Required
A4: [x] | B4: ENV-003 | C4: Current | D4: Environment & Startup | E4: Python virtual environment can be created | F4: Application dependencies are installed and the target environment is available. | G4: Run python -m venv venv in a clean checkout. | H4: Virtual environment is created without errors. | I4: P1 | J4: Installation | K4: Windows | L4: No | M4: Pass | O4: Fresh v4 local setup/install plus Flutter analyzer, 33 tests, and release web build passed on 2026-08-04. | P4: Codex SQA | Q4: 46238 | R4: Not Required
A5: [x] | B5: ENV-004 | C5: Current | D5: Environment & Startup | E5: Backend dependencies install | F5: Application dependencies are installed and the target environment is available. | G5: Run .\venv\Scripts\python.exe -m pip install -r .\backend\requirements.txt. | H5: All required packages install successfully. | I5: Release Gate | J5: Installation | K5: Windows | L5: No | M5: Pass | O5: Fresh v4 local setup/install plus Flutter analyzer, 33 tests, and release web build passed on 2026-08-04. | P5: Codex SQA | Q5: 46238 | R5: Not Required
A6: [x] | B6: ENV-005 | C6: Current | D6: Environment & Startup | E6: Python dependency integrity | F6: Application dependencies are installed and the target environment is available. | G6: Run .\venv\Scripts\python.exe -m pip check. | H6: Command reports no broken requirements. | I6: Release Gate | J6: Automated | K6: Backend | L6: Yes | M6: Pass | O6: Fresh v4 local setup/install plus Flutter analyzer, 33 tests, and release web build passed on 2026-08-04. | P6: Codex SQA | Q6: 46238 | R6: Not Required
A7: [x] | B7: ENV-006 | C7: Current | D7: Environment & Startup | E7: Flutter dependencies resolve | F7: Application dependencies are installed and the target environment is available. | G7: From frontend run flutter pub get. | H7: Flutter resolves dependencies without errors. | I7: Release Gate | J7: Installation | K7: Flutter | L7: No | M7: Pass | O7: Fresh v4 local setup/install plus Flutter analyzer, 33 tests, and release web build passed on 2026-08-04. | P7: Codex SQA | Q7: 46238 | R7: Not Required
A8: [ ] | B8: ENV-007 | C8: Current | D8: Environment & Startup | E8: Backend starts locally | F8: Application dependencies are installed and the target environment is available. | G8: Run .\venv\Scripts\python.exe .\backend\run.py and observe startup. | H8: FastAPI starts on the configured host/port and remains stable. | I8: Release Gate | J8: Smoke | K8: Backend | L8: No | M8: Not Run | R8: Not Required
A9: [ ] | B9: ENV-008 | C9: Current | D9: Environment & Startup | E9: Frontend starts in Chrome | F9: Application dependencies are installed and the target environment is available. | G9: Keep backend running; from frontend run flutter run -d chrome --dart-define=API_BASE_URL=http://127.0.0.1:5000. | H9: Chrome opens the application and the catalog loads. | I9: Release Gate | J9: Smoke | K9: Web | L9: No | M9: Not Run | R9: Not Required
A10: [x] | B10: ENV-009 | C10: Current | D10: Environment & Startup | E10: OneDrive-safe Flutter build output | F10: Application dependencies are installed and the target environment is available. | G10: Build or run from the OneDrive checkout using the configured .flutter_build path. | H10: Flutter creates assets without directory deletion or shader write failures. | I10: P1 | J10: Regression | K10: Windows/Web | L10: Partial | M10: Pass | O10: Fresh v4 local setup/install plus Flutter analyzer, 33 tests, and release web build passed on 2026-08-04. | P10: Codex SQA | Q10: 46238 | R10: Not Required
A11: [x] | B11: ENV-010 | C11: Current | D11: Environment & Startup | E11: Backend URL is configurable | F11: Application dependencies are installed and the target environment is available. | G11: Build/run with a nondefault API_BASE_URL and inspect requests. | H11: Frontend sends requests to the supplied URL, including image URLs and Monaco configuration. | I11: P1 | J11: Configuration | K11: Flutter | L11: Partial | M11: Pass | O11: Fresh v4 local setup/install plus Flutter analyzer, 33 tests, and release web build passed on 2026-08-04. | P11: Codex SQA | Q11: 46238 | R11: Not Required
A12: [ ] | B12: ENV-011 | C12: Current | D12: Environment & Startup | E12: Backend environment file loads | F12: Application dependencies are installed and the target environment is available. | G12: Place nonsecret test configuration in backend/.env; restart backend; inspect /health and relevant behavior. | H12: Settings load from backend/.env while the file remains ignored. | I12: P1 | J12: Configuration | K12: Backend | L12: Partial | M12: Not Run | R12: Not Required
A13: [x] | B13: API-001 | C13: Current | D13: Health & Public API | E13: Health endpoint responds | F13: Application dependencies are installed and the target environment is available. | G13: GET /health. | H13: HTTP 200 returns status ok, API version, database type, and sandbox type. | I13: Release Gate | J13: API | K13: Backend | L13: Yes | M13: Pass | O13: 76 backend tests passed; live API health/auth/CORS/assignment/image checks passed 13/13. | P13: Codex SQA | Q13: 46238 | R13: Not Required
A14: [x] | B14: API-002 | C14: Current | D14: Health & Public API | E14: OpenAPI documentation loads | F14: Application dependencies are installed and the target environment is available. | G14: Open /docs. | H14: Interactive FastAPI documentation loads and lists supported public/admin endpoints. | I14: P1 | J14: API | K14: Backend | L14: No | M14: N/A | O14: Intentionally disabled or unnecessary for the controlled v4 professor demo. | P14: Codex SQA | Q14: 46238 | R14: Not Required | S14: Preserved for a future broader study release where applicable.
A15: [x] | B15: API-003 | C15: Current | D15: Health & Public API | E15: Assignment list endpoint | F15: Application dependencies are installed and the target environment is available. | G15: GET /assignments and GET /assignments/. | H15: HTTP 200 returns four published assignments in numeric order. | I15: Release Gate | J15: API | K15: Backend | L15: Yes | M15: Pass | O15: 76 backend tests passed; live API health/auth/CORS/assignment/image checks passed 13/13. | P15: Codex SQA | Q15: 46238 | R15: Not Required
A16: [x] | B16: API-004 | C16: Current | D16: Health & Public API | E16: Assignment detail endpoint | F16: Application dependencies are installed and the target environment is available. | G16: GET /assignments/{id} for IDs 1 through 4. | H16: Each response contains student-visible assignment data and correct stable ID/version. | I16: Release Gate | J16: API | K16: Backend | L16: Yes | M16: Pass | O16: 76 backend tests passed; live API health/auth/CORS/assignment/image checks passed 13/13. | P16: Codex SQA | Q16: 46238 | R16: Not Required
A17: [x] | B17: API-005 | C17: Current | D17: Health & Public API | E17: Unknown assignment returns JSON 404 | F17: Application dependencies are installed and the target environment is available. | G17: GET /assignments/999. | H17: HTTP 404 returns the documented JSON error. | I17: P1 | J17: Negative API | K17: Backend | L17: Yes | M17: Pass | O17: 76 backend tests passed; live API health/auth/CORS/assignment/image checks passed 13/13. | P17: Codex SQA | Q17: 46238 | R17: Not Required
A18: [x] | B18: API-006 | C18: Current | D18: Health & Public API | E18: Assignment image endpoint | F18: Application dependencies are installed and the target environment is available. | G18: GET /images/1 and inspect content type/signature. | H18: HTTP 200 returns the expected PNG image. | I18: P1 | J18: API | K18: Backend | L18: Yes | M18: Pass | O18: 76 backend tests passed; live API health/auth/CORS/assignment/image checks passed 13/13. | P18: Codex SQA | Q18: 46238 | R18: Not Required
A19: [x] | B19: API-007 | C19: Current | D19: Health & Public API | E19: Unknown image returns JSON 404 | F19: Application dependencies are installed and the target environment is available. | G19: GET /images/999. | H19: HTTP 404 returns the documented JSON error. | I19: P2 | J19: Negative API | K19: Backend | L19: Yes | M19: Pass | O19: 76 backend tests passed; live API health/auth/CORS/assignment/image checks passed 13/13. | P19: Codex SQA | Q19: 46238 | R19: Not Required
A20: [x] | B20: API-008 | C20: Current | D20: Health & Public API | E20: Legacy grading compatibility | F20: Application dependencies are installed and the target environment is available. | G20: POST valid code to /grade/{id}. | H20: Legacy route returns the current structured grading contract. | I20: P1 | J20: Compatibility | K20: Backend | L20: Yes | M20: Pass | O20: 76 backend tests passed; live API health/auth/CORS/assignment/image checks passed 13/13. | P20: Codex SQA | Q20: 46238 | R20: Not Required
A21: [x] | B21: API-009 | C21: Current | D21: Health & Public API | E21: CORS permits configured frontend | F21: Application dependencies are installed and the target environment is available. | G21: Run frontend from the allowed origin and call public endpoints. | H21: Browser requests succeed without CORS errors; unapproved origins follow configured policy. | I21: P1 | J21: Integration | K21: Web/Backend | L21: Partial | M21: Pass | O21: 76 backend tests passed; live API health/auth/CORS/assignment/image checks passed 13/13. | P21: Codex SQA | Q21: 46238 | R21: Not Required
A22: [x] | B22: API-010 | C22: Current | D22: Health & Public API | E22: Malformed JSON is rejected | F22: Application dependencies are installed and the target environment is available. | G22: POST malformed JSON to a submission endpoint. | H22: Request returns controlled HTTP 400 without server crash or stack-trace leakage. | I22: P1 | J22: Negative API | K22: Backend | L22: Yes | M22: Pass | O22: 76 backend tests passed; live API health/auth/CORS/assignment/image checks passed 13/13. | P22: Codex SQA | Q22: 46238 | R22: Not Required
A23: [ ] | B23: API-011 | C23: Current | D23: Health & Public API | E23: Request timeout behavior is bounded | F23: Application dependencies are installed and the target environment is available. | G23: Simulate an unavailable or nonresponsive backend. | H23: Frontend leaves loading state within configured timeout and shows a recovery action. | I23: P1 | J23: Resilience | K23: Flutter | L23: Partial | M23: Not Run | R23: Not Required
A24: [x] | B24: CAT-001 | C24: Current | D24: Student Catalog & Navigation | E24: Catalog header and identity | F24: Application dependencies are installed and the target environment is available. | G24: Open the landing page. | H24: Robotics Programming Lab identity and subtitle render correctly. | I24: P2 | J24: UI | K24: Web/Mobile | L24: Yes | M24: Pass | O24: 32 Flutter tests passed; live Chrome student catalog showed four ordered assignments. | P24: Codex SQA | Q24: 46238 | R24: Not Required
A25: [x] | B25: CAT-002 | C25: Current | D25: Student Catalog & Navigation | E25: Four assignment cards render | F25: Application dependencies are installed and the target environment is available. | G25: Load the catalog. | H25: Exactly four current published assignment cards render with title, number, description, and action. | I25: Release Gate | J25: UI/API | K25: Web/Mobile | L25: Partial | M25: Pass | O25: 32 Flutter tests passed; live Chrome student catalog showed four ordered assignments. | P25: Codex SQA | Q25: 46238 | R25: Not Required
A26: [x] | B26: CAT-003 | C26: Current | D26: Student Catalog & Navigation | E26: Assignment ordering | F26: Application dependencies are installed and the target environment is available. | G26: Inspect catalog order. | H26: Assignments are ordered 1, 2, 3, 4. | I26: P1 | J26: UI | K26: Web/Mobile | L26: Yes | M26: Pass | O26: 32 Flutter tests passed; live Chrome student catalog showed four ordered assignments. | P26: Codex SQA | Q26: 46238 | R26: Not Required
A27: [x] | B27: CAT-004 | C27: Current | D27: Student Catalog & Navigation | E27: Progress summary default | F27: Application dependencies are installed and the target environment is available. | G27: Open with cleared local progress. | H27: Summary shows 0 of 4 completed and 0 percent. | I27: P1 | J27: State | K27: Web/Mobile | L27: Yes | M27: Pass | O27: 32 Flutter tests passed; live Chrome student catalog showed four ordered assignments. | P27: Codex SQA | Q27: 46238 | R27: Not Required
A28: [x] | B28: CAT-005 | C28: Current | D28: Student Catalog & Navigation | E28: Progress badges | F28: Application dependencies are installed and the target environment is available. | G28: Record attempts, completion, and solution reveal; return to catalog. | H28: Cards distinguish Not started, Attempted, Completed, last score, and Solution viewed states. | I28: P1 | J28: State | K28: Web/Mobile | L28: Yes | M28: Pass | O28: 32 Flutter tests passed; live Chrome student catalog showed four ordered assignments. | P28: Codex SQA | Q28: 46238 | R28: Not Required
A29: [x] | B29: CAT-006 | C29: Current | D29: Student Catalog & Navigation | E29: Open assignment | F29: Application dependencies are installed and the target environment is available. | G29: Select Start assignment on each card. | H29: Correct assignment workspace opens without losing assignment identity. | I29: Release Gate | J29: Navigation | K29: Web/Mobile | L29: Partial | M29: Pass | O29: 32 Flutter tests passed; live Chrome student catalog showed four ordered assignments. | P29: Codex SQA | Q29: 46238 | R29: Not Required
A30: [x] | B30: CAT-007 | C30: Current | D30: Student Catalog & Navigation | E30: Return to catalog | F30: Application dependencies are installed and the target environment is available. | G30: Open an assignment and use Home/back navigation. | H30: Catalog returns and refreshed progress is visible. | I30: P1 | J30: Navigation | K30: Web/Mobile | L30: Yes | M30: Pass | O30: 32 Flutter tests passed; live Chrome student catalog showed four ordered assignments. | P30: Codex SQA | Q30: 46238 | R30: Not Required
A31: [x] | B31: CAT-008 | C31: Current | D31: Student Catalog & Navigation | E31: Catalog loading state | F31: Application dependencies are installed and the target environment is available. | G31: Throttle assignment-list response. | H31: Skeleton/loading state renders without layout breakage. | I31: P2 | J31: UI/Resilience | K31: Web/Mobile | L31: Yes | M31: Pass | O31: 32 Flutter tests passed; live Chrome student catalog showed four ordered assignments. | P31: Codex SQA | Q31: 46238 | R31: Not Required
A32: [x] | B32: CAT-009 | C32: Current | D32: Student Catalog & Navigation | E32: Catalog error and retry | F32: Application dependencies are installed and the target environment is available. | G32: Stop backend, load catalog, restart backend, select retry. | H32: Actionable error appears and retry reloads assignments successfully. | I32: P1 | J32: Resilience | K32: Web/Mobile | L32: Yes | M32: Pass | O32: 32 Flutter tests passed; live Chrome student catalog showed four ordered assignments. | P32: Codex SQA | Q32: 46238 | R32: Not Required
A33: [x] | B33: CAT-010 | C33: Current | D33: Student Catalog & Navigation | E33: Instructor entry point | F33: Application dependencies are installed and the target environment is available. | G33: Select the instructor shield icon. | H33: Instructor assignment studio opens; student progress remains unaffected. | I33: P1 | J33: Navigation | K33: Web/Mobile | L33: Partial | M33: Pass | O33: 32 Flutter tests passed; live Chrome student catalog showed four ordered assignments. | P33: Codex SQA | Q33: 46238 | R33: Not Required
A34: [x] | B34: WRK-001 | C34: Current | D34: Assignment Workspace & Editor | E34: Correct assignment header | F34: Application dependencies are installed and the target environment is available. | G34: Open every assignment. | H34: Header shows assignment number, title, progress state, Home action, and AI toggle. | I34: P1 | J34: UI | K34: Web/Mobile | L34: Partial | M34: Pass | O34: Flutter tests passed; live Assignment 1 workspace, starter code, instructions, image, and results rendered. | P34: Codex SQA | Q34: 46238 | R34: Not Required
A35: [x] | B35: WRK-002 | C35: Current | D35: Assignment Workspace & Editor | E35: Starter code loads | F35: Application dependencies are installed and the target environment is available. | G35: Open a fresh assignment with no saved draft. | H35: Version-correct starter code populates the editor. | I35: Release Gate | J35: Integration | K35: Web/Mobile | L35: Partial | M35: Pass | O35: Flutter tests passed; live Assignment 1 workspace, starter code, instructions, image, and results rendered. | P35: Codex SQA | Q35: 46238 | R35: Not Required
A36: [x] | B36: WRK-003 | C36: Current | D36: Assignment Workspace & Editor | E36: Starter code is syntactically executable | F36: Application dependencies are installed and the target environment is available. | G36: Compile and submit starter code for assignments 1 through 4. | H36: Each starter runs without unintended SyntaxError or IndentationError. | I36: Release Gate | J36: Regression | K36: Backend | L36: Yes | M36: Pass | O36: Flutter tests passed; live Assignment 1 workspace, starter code, instructions, image, and results rendered. | P36: Codex SQA | Q36: 46238 | R36: Not Required
A37: [ ] | B37: WRK-004 | C37: Current | D37: Assignment Workspace & Editor | E37: Code editing | F37: Application dependencies are installed and the target environment is available. | G37: Type, delete, paste, and indent Python code. | H37: Editor accurately reflects edits and retains Python formatting. | I37: P1 | J37: UI | K37: Web | L37: No | M37: Not Run | R37: Not Required
A38: [x] | B38: WRK-005 | C38: Current | D38: Assignment Workspace & Editor | E38: Keyboard test execution | F38: Application dependencies are installed and the target environment is available. | G38: Press Ctrl+Enter while the editor is active. | H38: Exactly one test run starts. | I38: P1 | J38: Keyboard | K38: Web/Desktop | L38: Yes | M38: Pass | O38: Flutter tests passed; live Assignment 1 workspace, starter code, instructions, image, and results rendered. | P38: Codex SQA | Q38: 46238 | R38: Not Required
A39: [x] | B39: WRK-006 | C39: Current | D39: Assignment Workspace & Editor | E39: Run button execution | F39: Application dependencies are installed and the target environment is available. | G39: Select Run tests. | H39: Button enters running state, blocks duplicate execution, then returns to enabled state. | I39: Release Gate | J39: UI/Integration | K39: Web/Mobile | L39: Yes | M39: Pass | O39: Flutter tests passed; live Assignment 1 workspace, starter code, instructions, image, and results rendered. | P39: Codex SQA | Q39: 46238 | R39: Not Required
A40: [ ] | B40: WRK-007 | C40: Current | D40: Assignment Workspace & Editor | E40: Draft autosave | F40: Application dependencies are installed and the target environment is available. | G40: Edit code; wait for debounce; leave assignment. | H40: Draft is persisted for the assignment. | I40: P1 | J40: State | K40: Web/Mobile | L40: Partial | M40: Not Run | R40: Not Required
...

Sheet Assignment Matrix
A1: Checked? | B1: Assignment ID | C1: Stable ID | D1: Version | E1: Title | F1: Published | G1: Detail Loads | H1: Starter Compiles | I1: Starter Executes | J1: Official Solution | K1: Public Run | L1: Hidden Grading | M1: Evidence UI | N1: Solution Protection | O1: Hint Policy | P1: Simulation Config | Q1: Last Verified | R1: Evidence | S1: Notes
A2: [x] | B2: 1 | C2: robotics-assignment-1 | D2: 14 | E2: Obstacle Avoidance: Bug Algorithm Scenario 1 | F2: Pass | G2: Pass | H2: Pass | I2: Pass | J2: Pass | K2: Pass | L2: Pass | M2: Pass | N2: Pass | O2: Pass | P2: Pass | Q2: 46300 | R2: 2026-10-05 review fixes; see Review Fixes QA 2026-10-05 | S2: Verify consistent Euclidean/boundary distance and no embedded solution.
A3: [x] | B3: 2 | C3: robotics-assignment-2 | D3: 14 | E3: Obstacle Avoidance: Bug Algorithm Scenario 2 | F3: Pass | G3: Pass | H3: Pass | I3: Pass | J3: Pass | K3: Pass | L3: Pass | M3: Pass | N3: Pass | O3: Pass | P3: Pass | Q3: 46300 | R3: 2026-10-05 review fixes; see Review Fixes QA 2026-10-05 | S3: Verify four expected calculation variables and total path length.
A4: [x] | B4: 3 | C4: robotics-assignment-3 | D4: 15 | E4: Autonomous Robot Navigation in a Multi-Floor Office | F4: Pass | G4: Pass | H4: Pass | I4: Pass | J4: Pass | K4: Pass | L4: Pass | M4: Pass | N4: Pass | O4: Pass | P4: Pass | Q4: 46300 | R4: 2026-10-05 review fixes; see Review Fixes QA 2026-10-05 | S4: Verify movable obstacle activates the configured half-circle detour.
A5: [x] | B5: 4 | C5: robotics-assignment-4 | D5: 14 | E5: Selecting a Direction with a Simplified VFH | F5: Pass | G5: Pass | H5: Pass | I5: Pass | J5: Pass | K5: Pass | L5: Pass | M5: Pass | N5: Pass | O5: Pass | P5: Pass | Q5: 46300 | R5: 2026-10-05 review fixes; see Review Fixes QA 2026-10-05 | S5: Verify histogram and optimal-sector calculations.
A6: [x] | B6: 5 | C6: ros2-drive-forward | D6: 9 | E6: Drive Forward and Stop with ROS 2 | F6: Pass | G6: Pass | H6: Pass | I6: Pass | J6: Pass | K6: Pass | L6: Pass | M6: Pass | N6: Pass | O6: Pass | P6: Pass | Q6: 46300 | R6: 2026-10-05 review fixes; see Review Fixes QA 2026-10-05 | S6: Only controller.py is editable; the project tree and locked support files remain visible.
A7: [x] | B7: 6 | C7: ros2-obstacle-stop | D7: 9 | E7: Stop for an Obstacle with ROS 2 | F7: Pass | G7: Pass | H7: Pass | I7: Pass | J7: Pass | K7: Pass | L7: Pass | M7: Pass | N7: Pass | O7: Pass | P7: Pass | Q7: 46300 | R7: 2026-10-05 review fixes; see Review Fixes QA 2026-10-05 | S7: Only controller.py is editable; the project tree and locked support files remain visible.

Sheet Defect Log
A1: Defect ID | B1: Title | C1: Severity | D1: Category | E1: Environment | F1: Steps to Reproduce | G1: Expected | H1: Actual | I1: Status | J1: Owner | K1: Found Date | L1: Fix Version / Commit | M1: Retest Result | N1: Retest Date | O1: Evidence Link / Path | P1: Notes
P2: Enter the first real v4 defect here. No new product defect was found in the 2026-08-04 SQA run.
A3: SR-01 | B3: Safe math.dist wrongly blocked | C3: P1 | D3: Sandbox | E3: Local staging | F3: Use math.dist for a correct route | G3: 100% for equivalent correct method | H3: Blocked import attribute | I3: Fixed | J3: Development | K3: 46295.5 | L3: Uncommitted | M3: PASS | N3: 46295.5 | O3: STUDENT-2026-09-30 | P3: Safe math allowlist and equivalent-method tests
A4: SR-02 | B4: Extra return values earned full credit | C4: P1 | D4: Grading | E4: Local staging | F4: Return five values from four-value route function | G4: Invalid contract rejected | H4: 100% accepted | I4: Fixed | J4: Development | K4: 46295.5 | L4: Uncommitted | M4: PASS | N4: 46295.5 | O4: STUDENT-2026-09-30 | P4: Exact return-count validation and regression tests
A5: SR-03 | B5: Grading routes did not match valid Bug2 geometry | C5: P1 | D5: Assignment | E5: Local staging | F5: Review alternate grading scenarios | G5: M-line hit/leave and valid boundary segments | H5: Invalid route geometry | I5: Fixed | J5: Development | K5: 46295.5 | L5: Uncommitted | M5: PASS | N5: 46295.5 | O5: STUDENT-2026-09-30 | P5: Corrected scenarios, independently calculated expected values, version bump
A6: SR-04 | B6: Swapped approach and departure could pass | C6: P1 | D6: Grading | E6: Local staging | F6: Swap first and third return values | G6: Wrong order loses affected credit | H6: Equal lengths masked swap | I6: Fixed | J6: Development | K6: 46295.5 | L6: Uncommitted | M6: PASS | N6: 46295.5 | O6: STUDENT-2026-09-30 | P6: Distinct-distance scenario and all return permutations
A7: SR-05 | B7: Built-in hints criticized passing work | C7: P2 | D7: Tutor | E7: Local staging | F7: Request hint after all checks passed | G7: Acknowledge successful checks | H7: Failure-oriented advice | I7: Fixed | J7: Development | K7: 46295.5 | L7: Uncommitted | M7: PASS | N7: 46295.5 | O7: STUDENT-2026-09-30 | P7: Success and missing-evidence handling
A8: SR-06 | B8: Unsupported misconception labels | C8: P1 | D8: Research | E8: Local staging | F8: Request hints at different levels or AI feedback | G8: Only evidence-supported tags | H8: Hint level or model guess became a label | I8: Fixed | J8: Development | K8: 46295.5 | L8: Uncommitted | M8: PASS | N8: 46295.5 | O8: STUDENT-2026-09-30 | P8: Removed unsupported labels from built-in and AI feedback
A9: SR-07 | B9: Built-in hint UI absent with AI off | C9: P2 | D9: UI/API | E9: Local staging | F9: Run incomplete work with AI disabled | G9: Hint and progression available | H9: Only test details shown | I9: Fixed | J9: Development | K9: 46295.5 | L9: Uncommitted | M9: PASS | N9: 46295.5 | O9: STUDENT-2026-09-30 | P9: Initial deterministic hint without paid call or invented hint-request event
A10: SR-08 | B10: AI advised removing diagnostic prints | C10: P1 | D10: Tutor | E10: Local staging | F10: Ask about an extra return value | G10: Distinguish prints from return contract | H10: Wrong advice to remove prints | I10: Fixed | J10: Development | K10: 46295.5 | L10: Uncommitted | M10: PASS | N10: 46295.5 | O10: STUDENT-2026-09-30 | P10: Clarified tutor instructions; real request 9 retested
A11: SR-09 | B11: Scoring scope insufficiently explicit | C11: P2 | D11: Instructions | E11: Local staging | F11: Read assignments 1 and 2 as a new student | G11: Explain 25% weights and supplied-route scope | H11: Scoring across scenarios and scope unclear | I11: Fixed | J11: Development | K11: 46295.5 | L11: Uncommitted | M11: PASS | N11: 46295.5 | O11: STUDENT-2026-09-30 | P11: Added scope, partial-credit, return, numeric and AI rules
A12: OR-01 | B12: Hardcoded sector count accepted | C12: P1 | D12: Grading | E12: Local staging | F12: A4 return constant 360 | G12: Affected count check fails | H12: 100% before fix | I12: Fixed | J12: Development | K12: 46295.5 | L12: Reviewed staging changes | M12: PASS | N12: 46295.5 | O12: REMAINING-2026-09-30 | P12: Varied fill/seed counts and density ties; real regression
A13: OR-02 | B13: Late ROS stop accepted | C13: P1 | D13: Grading | E13: Local staging | F13: A5 stop after six seconds | G13: Safe-stop and hold checks fail | H13: 100% before fix | I13: Fixed | J13: Development | K13: 46295.5 | L13: Reviewed staging changes | M13: PASS | N13: 46295.5 | O13: REMAINING-2026-09-30 | P13: Command-relative clock; actual Docker result 70%
A14: OR-03 | B14: Incorrect ROS stop threshold accepted | C14: P1 | D14: Grading | E14: Local staging | F14: A6 threshold 0.50 or moves at 0.75 | G14: Obstacle criterion fails | H14: 100% before fix | I14: Fixed | J14: Development | K14: 46295.5 | L14: Reviewed staging changes | M14: PASS | N14: 46295.5 | O14: REMAINING-2026-09-30 | P14: Exact and near-threshold scans; actual result 80%
... A46: SQ-03 | B46: Default instructor password on shared staging and in docs | C46: High | D46: Security | E46: Neon staging | F46: Sign in to staging with the formerly published default instructor password | G46: Default credentials rejected | H46: Default credentials accepted | I46: Fixed | J46: Project owner | K46: 46297.5 | L46: 49e27f8 (guard and docs); staging account reset 2026-10-02 | M46: Pass | N46: 46297.75 | O46: Staging QA 2026-10-02 | P46: Guard and docs fixed; shared staging instructor password reset with owner approval; default rejected (401). Student account still uses the old default (separate follow-up)
A47: SQ-04 | B47: Demo session calls the research API and receives 409 | C47: Low | D47: Frontend | E47: Local staging | F47: Use the student demo and watch network requests | G47: Demo skips research tracking | H47: POST /research/sessions returns 409 per event | I47: Deferred | J47: Project owner | K47: 46297.5 | M47: Not Run | O47: Staging QA 2026-10-02 | P47: Server correctly rejects; no data stored. Deferred by owner (Phase 1)
A48: AR-01 | B48: A4 hidden cases passed readings as a list, so dict-copy solutions scored 0% | C48: Critical | D48: Grading | E48: Local staging (Windows) | F48: See the 2026-10-05 Assignments 1-6 review | G48: Fair, consistent assignment and grading | H48: A4 hidden cases passed readings as a list, so dict-copy solutions scored 0% | I48: Fixed | J48: Development | K48: 46300 | L48: e939dc3b | M48: Pass | N48: 46300 | O48: Assignment Review QA 2026-10-05
A49: AR-02 | B49: Sandbox errors showed worker line numbers; sandbox limits undocumented | C49: Medium | D49: Grading | E49: Local staging (Windows) | F49: See the 2026-10-05 Assignments 1-6 review | G49: Fair, consistent assignment and grading | H49: Sandbox errors showed worker line numbers; sandbox limits undocumented | I49: Fixed | J49: Development | K49: 46300 | L49: e939dc3b | M49: Pass | N49: 46300 | O49: Assignment Review QA 2026-10-05
A50: AR-03 | B50: A5 never-moving node earned 50% (straight-motion credit) | C50: High | D50: Grading | E50: Local staging (Windows) | F50: See the 2026-10-05 Assignments 1-6 review | G50: Fair, consistent assignment and grading | H50: A5 never-moving node earned 50% (straight-motion credit) | I50: Fixed | J50: Development | K50: 46300 | L50: e939dc3b | M50: Pass | N50: 46300 | O50: Assignment Review QA 2026-10-05
A51: AR-04 | B51: A6 always-stopped node earned 75% (stop and straight credit) | C51: High | D51: Grading | E51: Local staging (Windows) | F51: See the 2026-10-05 Assignments 1-6 review | G51: Fair, consistent assignment and grading | H51: A6 always-stopped node earned 75% (stop and straight credit) | I51: Fixed | J51: Development | K51: 46300 | L51: e939dc3b | M51: Pass | N51: 46300 | O51: Assignment Review QA 2026-10-05
A52: AR-05 | B52: VFH course page exposed instructor notes; practice pages conflicted with graded versions | C52: High | D52: Content | E52: Local staging (Windows) | F52: See the 2026-10-05 Assignments 1-6 review | G52: Fair, consistent assignment and grading | H52: VFH course page exposed instructor notes; practice pages conflicted with graded versions | I52: Fixed | J52: Development | K52: 46300 | L52: e939dc3b | M52: Pass | N52: 46300 | O52: Assignment Review QA 2026-10-05
A53: AR-06 | B53: A3 half-circle detour model geometrically misleading; barrier undescribed | C53: Medium | D53: Content | E53: Local staging (Windows) | F53: See the 2026-10-05 Assignments 1-6 review | G53: Fair, consistent assignment and grading | H53: A3 half-circle detour model geometrically misleading; barrier undescribed | I53: Fixed | J53: Development | K53: 46300 | L53: e939dc3b | M53: Pass | N53: 46300 | O53: Assignment Review QA 2026-10-05
A54: AR-07 | B54: A6 LaserScan infinity semantics and scan field of view unexplained | C54: Medium | D54: Content | E54: Local staging (Windows) | F54: See the 2026-10-05 Assignments 1-6 review | G54: Fair, consistent assignment and grading | H54: A6 LaserScan infinity semantics and scan field of view unexplained | I54: Fixed | J54: Development | K54: 46300 | L54: e939dc3b | M54: Pass | N54: 46300 | O54: Assignment Review QA 2026-10-05
A55: AR-08 | B55: A1/A2 objectives not assessed; turn-direction and diagram glyph issues | C55: Low | D55: Content | E55: Local staging (Windows) | F55: See the 2026-10-05 Assignments 1-6 review | G55: Fair, consistent assignment and grading | H55: A1/A2 objectives not assessed; turn-direction and diagram glyph issues | I55: Fixed | J55: Development | K55: 46300 | L55: e939dc3b | M55: Pass | N55: 46300 | O55: Assignment Review QA 2026-10-05
A56: AR-09 | B56: Untouched A5/A6 starters earned 20% and 10%; no ROS 2 primer | C56: Medium | D56: Grading | E56: Local staging (Windows) | F56: See the 2026-10-05 Assignments 1-6 review | G56: Fair, consistent assignment and grading | H56: Untouched A5/A6 starters earned 20% and 10%; no ROS 2 primer | I56: Fixed | J56: Development | K56: 46300 | L56: 40de925c | M56: Pass | N56: 46300 | O56: Assignment Review QA 2026-10-05
A57: AR-10 | B57: Sandbox rejected common numpy and Python spellings (np.deg2rad, np.array, np.where, math.pow, dict.update, _) | C57: Medium | D57: Grading | E57: Local staging (Windows) | F57: See the 2026-10-05 in-depth assignment review | G57: Fair, clear grading and instructions | H57: Sandbox rejected common numpy and Python spellings (np.deg2rad, np.array, np.where, math.pow, dict.update, _) | I57: Fixed | J57: Development | K57: 46300 | L57: 1af50897 | M57: Pass | N57: 46300 | O57: Review Fixes QA 2026-10-05
A58: AR-11 | B58: ROS crash text was raw rclpy traceback naming the grader instrumentation file | C58: High | D58: Grading | E58: Local staging (Windows) | F58: See the 2026-10-05 in-depth assignment review | G58: Fair, clear grading and instructions | H58: ROS crash text was raw rclpy traceback naming the grader instrumentation file | I58: Fixed | J58: Development | K58: 46300 | L58: 1af50897 | M58: Pass | N58: 46300 | O58: Review Fixes QA 2026-10-05
A59: AR-12 | B59: ROS checks showed no points; scaffold pass looked contradictory with 0% | C59: Low | D59: Frontend | E59: Local staging (Windows) | F59: See the 2026-10-05 in-depth assignment review | G59: Fair, clear grading and instructions | H59: ROS checks showed no points; scaffold pass looked contradictory with 0% | I59: Fixed | J59: Development | K59: 46300 | L59: 1af50897 | M59: Pass | N59: 46300 | O59: Review Fixes QA 2026-10-05
... A64: AR-17 | B64: Instruction layout and wording issues across A1-A6 and the VFH lesson | C64: Low | D64: Content | E64: Local staging (Windows) | F64: See the 2026-10-05 in-depth assignment review | G64: Fair, clear grading and instructions | H64: Instruction layout and wording issues across A1-A6 and the VFH lesson | I64: Fixed | J64: Development | K64: 46300 | L64: 1af50897 | M64: Pass | N64: 46300 | O64: Review Fixes QA 2026-10-05

Sheet Release Sign-off
A1: Release Sign-off
A2: Sign only after the Release Dashboard is complete, all Release Gate checks are resolved, and defects have retest evidence.
A4: Gate | B4: Required Evidence | C4: Status | D4: Owner | E4: Date | F4: Comments
A5: Automated backend tests | B5: pytest output | C5: Pass | D5: SQA | E5: 46296.833 | F5: 423 backend tests;65 focused Windows and Ubuntu22 checks; dependency/compile checks; actual Neon restart, shared analytics and historical-source reconciliation pass. Frontend unchanged.
A6: Flutter analysis/tests/build | B6: Command output | C6: Pass | D6: SQA | E6: 46296.5 | F6: Windows and Ubuntu22/24: Flutter analysis clean,91 tests passed, release builds passed.
A7: All published assignments validate | B7: Validation report | C7: Pass | D7: SQA | E7: 46296.5 | F7: All six versioned assignments remain published. Versions9,9,10,9,5,5.
A8: All official solutions pass | B8: Per-assignment evidence | C8: Pass | D8: SQA | E8: 46296.5 | F8: All six maintained answers100% on Windows API and Ubuntu22 graders.
A9: Desktop/mobile critical path | B9: Screenshots or test record | C9: Partial | D9: SQA | E9: 46296.5 | F9: All-six Windows rendered diagrams and A6 AI-panel behavior checked. Ubuntu containers pass stack/build checks; physical Ubuntu browser/hardware remains untested.
A10: Sandbox security checks | B10: Timeout/import/output/resource evidence | C10: Pass | D10: SQA | E10: 46296.5 | F10: Existing sandbox error/resource regression passes; actual isolated ROS answers and duplicate probes verified.
A11: Instructor workflow | B11: Account and assignment evidence | C11: Pass | D11: SQA | E11: 46262 | F11: Instructor APIs and UI support student/instructor create, edit, reset, activate, and deactivate flows.
A12: Authentication and account management | B12: Role, password, account, and isolation evidence | C12: Pass | D12: SQA | E12: 46262 | F12: Default student restored; Dave retained with zero progress; persistent browser progress is scoped by user ID.
A13: Secrets and source diff review | B13: Git evidence | C13: Pass | D13: SQA | E13: 46296.5 | F13: Scoped Git publication only. Secrets/configuration and unrelated user PDF moves excluded.
A14: Defect retest complete | B14: Defect IDs and retest evidence | C14: Partial | D14: SQA | E14: 46296.5 | F14: AI grounding and early-hint quality remain mitigated/PARTIAL. Other new defects have focused retest evidence. See AI-UBUNTU-2026-10-01.
A16: Approvals
A17: Role | B17: Name | C17: Decision | D17: Date | E17: Signature / Evidence | F17: Comments
A18: SQA Lead | C18: Pending
A19: Development Lead | C19: Pending
A20: Instructor / Curriculum Owner | C20: Pending
A21: Security / Platform Reviewer | C21: Pending
A22: Product / Research Lead | C22: Pending

Sheet Runbook
A1: SQA Execution Runbook
A2: Run commands from the repository root unless a different working directory is shown. Never put API keys or instructor tokens into the workbook.
A4: Section | B4: Purpose | C4: Command / Procedure | D4: Expected Result
A5: Install | B5: Create Python environment | C5: python -m venv venv | D5: venv directory is created
A6: Install | B6: Install backend packages | C6: .\venv\Scripts\python.exe -m pip install -r .\backend\requirements.txt | D6: Installation succeeds
A7: Install | B7: Install Flutter packages | C7: Set-Location .\frontend; flutter pub get; Set-Location .. | D7: Dependency resolution succeeds
A8: Run | B8: Start backend (Terminal 1) | C8: .\venv\Scripts\python.exe .\backend\run.py | D8: Backend remains running at http://127.0.0.1:5000
A9: Run | B9: Start frontend (Terminal 2) | C9: Set-Location .\frontend; flutter run -d chrome --dart-define=API_BASE_URL=http://127.0.0.1:5000 | D9: Chrome opens the catalog
A10: Backend QA | B10: Run backend tests | C10: Set-Location .\backend; ..\venv\Scripts\python.exe -m pytest -q | D10: All maintained tests pass
A11: Backend QA | B11: Check package integrity | C11: Set-Location .\backend; ..\venv\Scripts\python.exe -m pip check | D11: No broken requirements
A12: Backend QA | B12: Compile Python modules | C12: Set-Location .\backend; ..\venv\Scripts\python.exe -m compileall -q . | D12: No compilation errors
A13: Frontend QA | B13: Static analysis | C13: Set-Location .\frontend; flutter analyze | D13: No issues found
A14: Frontend QA | B14: Widget/state tests | C14: Set-Location .\frontend; flutter test | D14: All tests pass
A15: Frontend QA | B15: Release web build | C15: Set-Location .\frontend; flutter build web --dart-define=API_BASE_URL=http://127.0.0.1:5000 | D15: Build succeeds in .flutter_build\web
... A43: Production | B43: Promote an approved immutable release | C43: .\scripts\promote-release.ps1 -ReleaseTag v4.0.0 -ConfirmProduction | D43: After explicit approval, the exact staging SHA and tag reach production atomically
A44: Severity and Status Definitions
A45: Value | B45: Meaning | C45: Release Effect | D45: Required Action
A46: Critical | B46: Security compromise, data loss, unsafe execution, or platform unavailable | C46: Immediate stop | D46: Fix before any release
A47: High | B47: Critical workflow incorrect or inaccessible with no acceptable workaround | C47: Blocks release | D47: Fix and retest
A48: Medium | B48: Important behavior incorrect with limited workaround | C48: Risk decision required | D48: Plan fix and document
A49: Low | B49: Minor presentation, usability, or documentation issue | C49: Usually does not block | D49: Track and prioritize
A50: Not Run | B50: Test has not been executed | C50: Release incomplete for current scope | D50: Execute or justify N/A
A51: Pass | B51: Actual result matches expected result | C51: Contributes to readiness | D51: Attach evidence
A52: Fail | B52: Actual result does not match expected result | C52: Release Gate failures block | D52: Create defect and fix
A53: Blocked | B53: External/environment condition prevents execution | C53: Release Gate blocks unless explicitly waived | D53: Document blocker and owner
A54: N/A | B54: Test does not apply to this release/environment | C54: Excluded with justification | D54: Explain in Notes
A55: Deferred | B55: Planned future capability not in current release | C55: Excluded from current completion | D55: Review during planning
A57: Single QA workbook policy
A58: Master Checklist | B58: Current checklist | C58: Update affected cases and attach evidence | D58: Do not replace historical results
A59: QA Run History | B59: Imported historical check rows | C59: Append new dated checks with commit, environment, expected / actual and reason | D59: Use PASS, FAIL, PARTIAL, BLOCKED or NOT RUN
A60: QA Report Index | B60: Original report identifiers and hashes | C60: Find the report ID and archive start row | D60: Original paths are provenance, not file links
A61: QA Report Archive | B61: Complete historical report text | C61: Filter by Report ID; lines retain original order | D61: Historical results are not a new QA run
A62: Consolidation 2026-09-30 | B62: 29 reports; 736 recorded check rows; 2220 source lines | C62: No application tests rerun for documentation consolidation | D62: No commit or push performed

Sheet Lists
A1: Status | B1: Priority | C1: Automation | D1: Check | E1: Retest | F1: Defect Status | G1: Severity | H1: Decision | I1: Scope | J1: Test Type
A2: Not Run | B2: Release Gate | C2: Yes | D2: [ ] | E2: Not Required | F2: Open | G2: Critical | H2: Pending | I2: Current | J2: Automated
A3: Pass | B3: P0 | C3: Partial | D3: [x] | E3: Pass | F3: In Progress | G3: High | H3: Approved | I3: Future | J3: API
A4: Fail | B4: P1 | C4: No | E4: Fail | F4: Fixed | G4: Medium | H4: Rejected | J4: Integration
A5: Blocked | B5: P2 | E5: Blocked | F5: Closed | G5: Low | H5: Conditional | J5: Manual
A6: N/A | E6: Not Run | F6: Deferred | J6: Security
A7: Deferred | J7: Accessibility
J8: Performance
J9: Content Review
J10: Process

Sheet V5.2 Neon & Accounts
A1: V5.2 Neon and Account Management - SQA Evidence
A2: Windows local staging verification | 2026-08-28 | Implementation: staging main v5.3; final QA follow-up local
A4: Check ID | B4: Area | C4: Verification | D4: Expected | E4: Result | F4: Evidence | G4: Limitation
A5: V52-001 | B5: Neon | C5: Dedicated staging database | D5: Use robotics_lab_staging without altering old neondb | E5: PASS | F5: Launcher selected dedicated Neon database; old database was preserved. | G5: Internet and Neon availability are required.
A6: V52-002 | B6: Migration | C6: Local-to-Neon transfer | D6: All application records migrate | E6: PASS | F6: 376 rows migrated across 10 application tables. | G6: Migration report remains private.
A7: V52-003 | B7: Persistence | C7: Neon restart | D7: Counts and study history survive restart | E7: PASS | F7: 3 users, 6 assignments, 65 submissions, 2 activities, 44 events, and 22 sessions before and after restart. | G7: No public deployment was performed.
A8: V52-004 | B8: Accounts | C8: Default student credential | D8: Required prototype credential verifies | E8: PASS | F8: Password hash verified without writing plaintext to the workbook. | G8: Change before a real classroom study.
A9: V52-005 | B9: Accounts | C9: Dave retained | D9: Account active with no inherited work | E9: PASS | F9: 0 attempts and 0 completed assignments in Neon. | G9: A stale browser page must refresh after frontend update.
A10: V52-006 | B10: Progress | C10: Cross-account isolation | D10: One student cannot inherit another student's local progress | E10: PASS | F10: Dedicated user-ID storage regression test passed. | G10: Legacy data migrates only to the default prototype student.
A11: V52-007 | B11: Instructor Studio | C11: Manage both roles | D11: Create/list/edit/reset/activate/deactivate students and instructors | E11: PASS | F11: Backend role flows and Flutter UI regression tests passed. | G11: Deletion is intentionally replaced with deactivation.
A12: V52-008 | B12: Safety | C12: Instructor lockout prevention | D12: Cannot self-disable or disable the last active instructor | E12: PASS | F12: Focused API test passed. | G12: A second instructor is required before deactivating the first.
A13: V52-009 | B13: JSON | C13: Tracked password-free account roster | D13: Every clone receives account metadata while passwords and hashes remain outside Git | E13: PASS | F13: backend/data/study_accounts.json contains metadata only; backend rejects temporary passwords in the canonical roster. | G13: Create and reset passwords through Instructor Studio; hashes remain in Neon.
A14: V52-010 | B14: Neon | C14: Neon-only database runtime | D14: Startup requires the authorized Neon staging database; no local PostgreSQL, dump restore, backup worker, or device lock remains | E14: PASS | F14: Windows start/stop, private-config validation, Alembic migration, runtime-state, and service health checks passed. Internet and Neon availability are required. | G14: Requires internet access and Neon availability; no offline database mode remains.
